Workbook

Sheet Dashboard
B3: Estado de Avance — Nuevos Módulos SIRH | I3: 🚦 ESTADO GENERAL | K3: PLAZOS | M3: 📈 AVANCE
B4: ="Actualizado: "&TEXT(TODAY(),"dd/mm/yyyy")&" · Proyecto SIRH · MINSAL · "&Indicadores!B3&" actividades en 10 etapas · 7 módulos" -> Actualizado: 05/08/2026 · Proyecto SIRH · MINSAL · 294 actividades en 10 etapas · 7 módulos | I4: =Indicadores!B14 -> NORMAL | K4: =IF(Indicadores!B10=0,"✅ Verde",IF(Indicadores!B10<=2,"⚠️ Amarillo","🔴 Rojo")) -> ✅ Verde | M4: =Indicadores!B13 -> 0.054421769
I5: 🎯 Avance general del proyecto | K5: =REPT("█",ROUND((Indicadores!B13)*34,0))&REPT("░",34-ROUND((Indicadores!B13)*34,0))&" "&TEXT(Indicadores!B13,"0.0%") -> ██░░░░░░░░░░░░░░░░░░░░░░░░░░░░░░░░ 5.4%
B7: Indicadores clave | H7: 294 actividades · 10 etapas · 7 módulos
B10: 📋 TOTAL ACTIVIDADES | D10: ✅ FINALIZADAS | F10: 🔄 EN CURSO | H10: 🚨 ATRASADAS | J10: ⏸️ NO INICIADAS | L10: 📅 PROGRAMADAS
B11: =Indicadores!B3 -> 294 | D11: =Indicadores!B4 -> 16 | F11: =Indicadores!B6 -> 2 | H11: =Indicadores!B10 -> 0 | J11: =Indicadores!B9 -> 0 | L11: =Indicadores!B8 -> 276
B14: Avance general | H14: Requerimientos + actividades
B16: 🗂️ Avance de actividades | D16: =REPT("█",ROUND((Indicadores!B13)*34,0))&REPT("░",34-ROUND((Indicadores!B13)*34,0))&" "&TEXT(Indicadores!B13,"0.0%") -> ██░░░░░░░░░░░░░░░░░░░░░░░░░░░░░░░░ 5.4%
B17: 📦 Requerimientos — Listos | D17: =REPT("█",ROUND((Indicadores!B117)*34,0))&REPT("░",34-ROUND((Indicadores!B117)*34,0))&" "&TEXT(Indicadores!B117,"0.0%") -> ███████████████░░░░░░░░░░░░░░░░░░░ 44.7%
B18: 🧩 Requerimientos — Listos + Maqueta | D18: =REPT("█",ROUND((Indicadores!B118)*34,0))&REPT("░",34-ROUND((Indicadores!B118)*34,0))&" "&TEXT(Indicadores!B118,"0.0%") -> █████████████████░░░░░░░░░░░░░░░░░ 48.8%
B20: Avance por Etapa | H20: % actividades finalizadas / etapa | I20: Actividades por Responsable
B38: Avance por Módulo | H38: % actividades finalizadas / módulo | I38: Estado general de actividades
B56: Requerimientos por Módulo | H56: Listo · Maqueta · Pendiente · Observado | I56: Componentes destacados
I58: 🏆 Mejor avance: | K58: =INDEX(Indicadores!A54:A95,MATCH(MAX(Indicadores!F54:F95),Indicadores!F54:F95,0)) -> Constitución del equipo de Trabajo
I59: % avance: | K59: =MAX(Indicadores!F54:F95) -> 0.14285714
I61: ⚠️ Menor avance: | K61: =INDEX(Indicadores!A54:A95,MATCH(MIN(Indicadores!F54:F95),Indicadores!F54:F95,0)) -> Integraciones.
I62: % avance: | K62: =MIN(Indicadores!F54:F95) -> 0
B76: Notas de esta versión: se corrigió la fórmula de Estado en la hoja Etapas (la referencia a 'Tablas y Glosario'!F1 no estaba anclada con $, por lo que cada fila comparaba contra una celda de fecha distinta y en su mayoría vacía) y la fórmula de desglose por Responsable en Indicadores (las columnas C:J referenciaban columnas incorrectas de Etapas). Los gráficos dinámicos originales (basados en tablas dinámicas) se reemplazaron por gráficos nativos con fórmulas para mayor estabilidad y compatibilidad.

Sheet Indicadores
A1: Resumen Ejecutivo
A2: Indicador | B2: Valor
A3: Total actividades | B3: =COUNTA(Etapas!D2:D400) -> 294
A4: Finalizadas | B4: =COUNTIF(Etapas!$Q$2:$Q$400,"Finalizado")+COUNTIF(Etapas!$Q$2:$Q$400,"Finalizado anticipado") -> 16
A5: Finalizadas con desfase | B5: =COUNTIF(Etapas!$Q$2:$Q$400,"Finalizado con desfase") -> 0
A6: En curso | B6: =COUNTIF(Etapas!$Q$2:$Q$400,"En curso")+COUNTIF(Etapas!$Q$2:$Q$400,"Inicio anticipado") -> 2
A7: Inicio retrasado (en curso) | B7: =COUNTIF(Etapas!$Q$2:$Q$400,"Inicio retrasado") -> 0
A8: Programadas | B8: =COUNTIF(Etapas!$Q$2:$Q$400,"Programado") -> 276
A9: No iniciadas | B9: =COUNTIF(Etapas!$Q$2:$Q$400,"No iniciado") -> 0
A10: Atrasadas | B10: =COUNTIF(Etapas!$Q$2:$Q$400,"Atrasado") -> 0
A11: No planificadas | B11: =COUNTIF(Etapas!$Q$2:$Q$400,"No planificado") -> 0
A12: COMPLETAR (falta info) | B12: =COUNTIF(Etapas!$Q$2:$Q$400,"COMPLETAR") -> 0
A13: % avance | B13: =IF(B3=0,0,(B4+B5)/B3) -> 0.054421769
A14: Estado general | B14: =IF(B10>2,"CRÍTICO",IF(B10>0,"EN RIESGO","NORMAL")) -> NORMAL
A17: Resumen por Módulo
A19: Módulo | B19: Total | C19: COMPLETAR | D19: Falta planificación | E19: Programado | F19: No iniciado | G19: Inicio anticipado | H19: En curso | I19: Inicio retrasado | J19: Atrasado | K19: Finalizado anticipado | L19: Finalizado | M19: Finalizado con desfase | N19: % Avance
A20: AutoAtención | B20: =COUNTIF(Etapas!$B$2:$B$400,$A20) -> 42 | C20: =COUNTIFS(Etapas!$B$2:$B$400,$A20,Etapas!$Q$2:$Q$400,C$19) -> 0 | D20: =COUNTIFS(Etapas!$B$2:$B$400,$A20,Etapas!$Q$2:$Q$400,D$19) -> 0 | E20: =COUNTIFS(Etapas!$B$2:$B$400,$A20,Etapas!$Q$2:$Q$400,E$19) -> 24 | F20: =COUNTIFS(Etapas!$B$2:$B$400,$A20,Etapas!$Q$2:$Q$400,F$19) -> 0 | G20: =COUNTIFS(Etapas!$B$2:$B$400,$A20,Etapas!$Q$2:$Q$400,G$19) -> 0 | H20: =COUNTIFS(Etapas!$B$2:$B$400,$A20,Etapas!$Q$2:$Q$400,H$19) -> 2 | I20: =COUNTIFS(Etapas!$B$2:$B$400,$A20,Etapas!$Q$2:$Q$400,I$19) -> 0 | J20: =COUNTIFS(Etapas!$B$2:$B$400,$A20,Etapas!$Q$2:$Q$400,J$19) -> 0 | ... M20: =COUNTIFS(Etapas!$B$2:$B$400,$A20,Etapas!$Q$2:$Q$400,M$19) -> 0 | N20: =IF(B20=0,0,(K20+L20+M20)/B20) -> 0.38095238
A21: RAD | B21: =COUNTIF(Etapas!$B$2:$B$400,$A21) -> 42 | C21: =COUNTIFS(Etapas!$B$2:$B$400,$A21,Etapas!$Q$2:$Q$400,C$19) -> 0 | D21: =COUNTIFS(Etapas!$B$2:$B$400,$A21,Etapas!$Q$2:$Q$400,D$19) -> 0 | E21: =COUNTIFS(Etapas!$B$2:$B$400,$A21,Etapas!$Q$2:$Q$400,E$19) -> 42 | F21: =COUNTIFS(Etapas!$B$2:$B$400,$A21,Etapas!$Q$2:$Q$400,F$19) -> 0 | G21: =COUNTIFS(Etapas!$B$2:$B$400,$A21,Etapas!$Q$2:$Q$400,G$19) -> 0 | H21: =COUNTIFS(Etapas!$B$2:$B$400,$A21,Etapas!$Q$2:$Q$400,H$19) -> 0 | I21: =COUNTIFS(Etapas!$B$2:$B$400,$A21,Etapas!$Q$2:$Q$400,I$19) -> 0 | J21: =COUNTIFS(Etapas!$B$2:$B$400,$A21,Etapas!$Q$2:$Q$400,J$19) -> 0 | ... M21: =COUNTIFS(Etapas!$B$2:$B$400,$A21,Etapas!$Q$2:$Q$400,M$19) -> 0 | N21: =IF(B21=0,0,(K21+L21+M21)/B21) -> 0
A22: Licencias Médicas | B22: =COUNTIF(Etapas!$B$2:$B$400,$A22) -> 42 | C22: =COUNTIFS(Etapas!$B$2:$B$400,$A22,Etapas!$Q$2:$Q$400,C$19) -> 0 | D22: =COUNTIFS(Etapas!$B$2:$B$400,$A22,Etapas!$Q$2:$Q$400,D$19) -> 0 | E22: =COUNTIFS(Etapas!$B$2:$B$400,$A22,Etapas!$Q$2:$Q$400,E$19) -> 42 | F22: =COUNTIFS(Etapas!$B$2:$B$400,$A22,Etapas!$Q$2:$Q$400,F$19) -> 0 | G22: =COUNTIFS(Etapas!$B$2:$B$400,$A22,Etapas!$Q$2:$Q$400,G$19) -> 0 | H22: =COUNTIFS(Etapas!$B$2:$B$400,$A22,Etapas!$Q$2:$Q$400,H$19) -> 0 | I22: =COUNTIFS(Etapas!$B$2:$B$400,$A22,Etapas!$Q$2:$Q$400,I$19) -> 0 | J22: =COUNTIFS(Etapas!$B$2:$B$400,$A22,Etapas!$Q$2:$Q$400,J$19) -> 0 | ... M22: =COUNTIFS(Etapas!$B$2:$B$400,$A22,Etapas!$Q$2:$Q$400,M$19) -> 0 | N22: =IF(B22=0,0,(K22+L22+M22)/B22) -> 0
A23: Calificaciones | B23: =COUNTIF(Etapas!$B$2:$B$400,$A23) -> 42 | C23: =COUNTIFS(Etapas!$B$2:$B$400,$A23,Etapas!$Q$2:$Q$400,C$19) -> 0 | D23: =COUNTIFS(Etapas!$B$2:$B$400,$A23,Etapas!$Q$2:$Q$400,D$19) -> 0 | E23: =COUNTIFS(Etapas!$B$2:$B$400,$A23,Etapas!$Q$2:$Q$400,E$19) -> 42 | F23: =COUNTIFS(Etapas!$B$2:$B$400,$A23,Etapas!$Q$2:$Q$400,F$19) -> 0 | G23: =COUNTIFS(Etapas!$B$2:$B$400,$A23,Etapas!$Q$2:$Q$400,G$19) -> 0 | H23: =COUNTIFS(Etapas!$B$2:$B$400,$A23,Etapas!$Q$2:$Q$400,H$19) -> 0 | I23: =COUNTIFS(Etapas!$B$2:$B$400,$A23,Etapas!$Q$2:$Q$400,I$19) -> 0 | J23: =COUNTIFS(Etapas!$B$2:$B$400,$A23,Etapas!$Q$2:$Q$400,J$19) -> 0 | ... M23: =COUNTIFS(Etapas!$B$2:$B$400,$A23,Etapas!$Q$2:$Q$400,M$19) -> 0 | N23: =IF(B23=0,0,(K23+L23+M23)/B23) -> 0
A24: FORCAP | B24: =COUNTIF(Etapas!$B$2:$B$400,$A24) -> 42 | C24: =COUNTIFS(Etapas!$B$2:$B$400,$A24,Etapas!$Q$2:$Q$400,C$19) -> 0 | D24: =COUNTIFS(Etapas!$B$2:$B$400,$A24,Etapas!$Q$2:$Q$400,D$19) -> 0 | E24: =COUNTIFS(Etapas!$B$2:$B$400,$A24,Etapas!$Q$2:$Q$400,E$19) -> 42 | F24: =COUNTIFS(Etapas!$B$2:$B$400,$A24,Etapas!$Q$2:$Q$400,F$19) -> 0 | G24: =COUNTIFS(Etapas!$B$2:$B$400,$A24,Etapas!$Q$2:$Q$400,G$19) -> 0 | H24: =COUNTIFS(Etapas!$B$2:$B$400,$A24,Etapas!$Q$2:$Q$400,H$19) -> 0 | I24: =COUNTIFS(Etapas!$B$2:$B$400,$A24,Etapas!$Q$2:$Q$400,I$19) -> 0 | J24: =COUNTIFS(Etapas!$B$2:$B$400,$A24,Etapas!$Q$2:$Q$400,J$19) -> 0 | ... M24: =COUNTIFS(Etapas!$B$2:$B$400,$A24,Etapas!$Q$2:$Q$400,M$19) -> 0 | N24: =IF(B24=0,0,(K24+L24+M24)/B24) -> 0
A25: VALS | B25: =COUNTIF(Etapas!$B$2:$B$400,$A25) -> 42 | C25: =COUNTIFS(Etapas!$B$2:$B$400,$A25,Etapas!$Q$2:$Q$400,C$19) -> 0 | D25: =COUNTIFS(Etapas!$B$2:$B$400,$A25,Etapas!$Q$2:$Q$400,D$19) -> 0 | E25: =COUNTIFS(Etapas!$B$2:$B$400,$A25,Etapas!$Q$2:$Q$400,E$19) -> 42 | F25: =COUNTIFS(Etapas!$B$2:$B$400,$A25,Etapas!$Q$2:$Q$400,F$19) -> 0 | G25: =COUNTIFS(Etapas!$B$2:$B$400,$A25,Etapas!$Q$2:$Q$400,G$19) -> 0 | H25: =COUNTIFS(Etapas!$B$2:$B$400,$A25,Etapas!$Q$2:$Q$400,H$19) -> 0 | I25: =COUNTIFS(Etapas!$B$2:$B$400,$A25,Etapas!$Q$2:$Q$400,I$19) -> 0 | J25: =COUNTIFS(Etapas!$B$2:$B$400,$A25,Etapas!$Q$2:$Q$400,J$19) -> 0 | ... M25: =COUNTIFS(Etapas!$B$2:$B$400,$A25,Etapas!$Q$2:$Q$400,M$19) -> 0 | N25: =IF(B25=0,0,(K25+L25+M25)/B25) -> 0
A26: Portal SIRH | B26: =COUNTIF(Etapas!$B$2:$B$400,$A26) -> 42 | C26: =COUNTIFS(Etapas!$B$2:$B$400,$A26,Etapas!$Q$2:$Q$400,C$19) -> 0 | D26: =COUNTIFS(Etapas!$B$2:$B$400,$A26,Etapas!$Q$2:$Q$400,D$19) -> 0 | E26: =COUNTIFS(Etapas!$B$2:$B$400,$A26,Etapas!$Q$2:$Q$400,E$19) -> 42 | F26: =COUNTIFS(Etapas!$B$2:$B$400,$A26,Etapas!$Q$2:$Q$400,F$19) -> 0 | G26: =COUNTIFS(Etapas!$B$2:$B$400,$A26,Etapas!$Q$2:$Q$400,G$19) -> 0 | H26: =COUNTIFS(Etapas!$B$2:$B$400,$A26,Etapas!$Q$2:$Q$400,H$19) -> 0 | I26: =COUNTIFS(Etapas!$B$2:$B$400,$A26,Etapas!$Q$2:$Q$400,I$19) -> 0 | J26: =COUNTIFS(Etapas!$B$2:$B$400,$A26,Etapas!$Q$2:$Q$400,J$19) -> 0 | ... M26: =COUNTIFS(Etapas!$B$2:$B$400,$A26,Etapas!$Q$2:$Q$400,M$19) -> 0 | N26: =IF(B26=0,0,(K26+L26+M26)/B26) -> 0
A29: Resumen por Responsable
A31: Responsable | B31: Total | C31: COMPLETAR | D31: Falta planificación | E31: Programado | F31: No iniciado | G31: Inicio anticipado | H31: En curso | I31: Inicio retrasado | J31: Atrasado | K31: Finalizado anticipado | L31: Finalizado | M31: Finalizado con desfase | N31: % Responsabilidad
A32: MINSAL | B32: =COUNTIF(Etapas!$K$2:$K$400,$A32) -> 161 | C32: =COUNTIFS(Etapas!$K$2:$K$400,$A32,Etapas!$Q$2:$Q$400,C$31) -> 0 | D32: =COUNTIFS(Etapas!$K$2:$K$400,$A32,Etapas!$Q$2:$Q$400,D$31) -> 0 | E32: =COUNTIFS(Etapas!$K$2:$K$400,$A32,Etapas!$Q$2:$Q$400,E$31) -> 149 | F32: =COUNTIFS(Etapas!$K$2:$K$400,$A32,Etapas!$Q$2:$Q$400,F$31) -> 0 | G32: =COUNTIFS(Etapas!$K$2:$K$400,$A32,Etapas!$Q$2:$Q$400,G$31) -> 0 | H32: =COUNTIFS(Etapas!$K$2:$K$400,$A32,Etapas!$Q$2:$Q$400,H$31) -> 0 | I32: =COUNTIFS(Etapas!$K$2:$K$400,$A32,Etapas!$Q$2:$Q$400,I$31) -> 0 | J32: =COUNTIFS(Etapas!$K$2:$K$400,$A32,Etapas!$Q$2:$Q$400,J$31) -> 0 | ... M32: =COUNTIFS(Etapas!$K$2:$K$400,$A32,Etapas!$Q$2:$Q$400,M$31) -> 0 | N32: =IF($B$32+$B$33=0,0,B32/($B$32+$B$33)) -> 0.54761905
A33: PROVEEDOR | B33: =COUNTIF(Etapas!$K$2:$K$400,$A33) -> 133 | C33: =COUNTIFS(Etapas!$K$2:$K$400,$A33,Etapas!$Q$2:$Q$400,C$31) -> 0 | D33: =COUNTIFS(Etapas!$K$2:$K$400,$A33,Etapas!$Q$2:$Q$400,D$31) -> 0 | E33: =COUNTIFS(Etapas!$K$2:$K$400,$A33,Etapas!$Q$2:$Q$400,E$31) -> 127 | F33: =COUNTIFS(Etapas!$K$2:$K$400,$A33,Etapas!$Q$2:$Q$400,F$31) -> 0 | G33: =COUNTIFS(Etapas!$K$2:$K$400,$A33,Etapas!$Q$2:$Q$400,G$31) -> 0 | H33: =COUNTIFS(Etapas!$K$2:$K$400,$A33,Etapas!$Q$2:$Q$400,H$31) -> 2 | I33: =COUNTIFS(Etapas!$K$2:$K$400,$A33,Etapas!$Q$2:$Q$400,I$31) -> 0 | J33: =COUNTIFS(Etapas!$K$2:$K$400,$A33,Etapas!$Q$2:$Q$400,J$31) -> 0 | ... M33: =COUNTIFS(Etapas!$K$2:$K$400,$A33,Etapas!$Q$2:$Q$400,M$31) -> 0 | N33: =IF($B$32+$B$33=0,0,B33/($B$32+$B$33)) -> 0.45238095
A36: Resumen por Etapa
A38: Etapa | B38: Total | C38: COMPLETAR | D38: Falta planificación | E38: Programado | F38: No iniciado | G38: Inicio anticipado | H38: En curso | I38: Inicio retrasado | J38: Atrasado | K38: Finalizado anticipado | L38: Finalizado | M38: Finalizado con desfase | N38: % Avance
A39: 1. Preparación | B39: =COUNTIF(Etapas!$D$2:$D$400,$A39) -> 28 | C39: =COUNTIFS(Etapas!$D$2:$D$400,$A39,Etapas!$Q$2:$Q$400,C$38) -> 0 | D39: =COUNTIFS(Etapas!$D$2:$D$400,$A39,Etapas!$Q$2:$Q$400,D$38) -> 0 | E39: =COUNTIFS(Etapas!$D$2:$D$400,$A39,Etapas!$Q$2:$Q$400,E$38) -> 24 | F39: =COUNTIFS(Etapas!$D$2:$D$400,$A39,Etapas!$Q$2:$Q$400,F$38) -> 0 | G39: =COUNTIFS(Etapas!$D$2:$D$400,$A39,Etapas!$Q$2:$Q$400,G$38) -> 0 | H39: =COUNTIFS(Etapas!$D$2:$D$400,$A39,Etapas!$Q$2:$Q$400,H$38) -> 0 | I39: =COUNTIFS(Etapas!$D$2:$D$400,$A39,Etapas!$Q$2:$Q$400,I$38) -> 0 | J39: =COUNTIFS(Etapas!$D$2:$D$400,$A39,Etapas!$Q$2:$Q$400,J$38) -> 0 | ... M39: =COUNTIFS(Etapas!$D$2:$D$400,$A39,Etapas!$Q$2:$Q$400,M$38) -> 0 | N39: =IF(B39=0,0,(K39+L39+M39)/B39) -> 0.14285714
A40: 2. Definición Funcional | B40: =COUNTIF(Etapas!$D$2:$D$400,$A40) -> 35 | C40: =COUNTIFS(Etapas!$D$2:$D$400,$A40,Etapas!$Q$2:$Q$400,C$38) -> 0 | D40: =COUNTIFS(Etapas!$D$2:$D$400,$A40,Etapas!$Q$2:$Q$400,D$38) -> 0 | E40: =COUNTIFS(Etapas!$D$2:$D$400,$A40,Etapas!$Q$2:$Q$400,E$38) -> 30 | F40: =COUNTIFS(Etapas!$D$2:$D$400,$A40,Etapas!$Q$2:$Q$400,F$38) -> 0 | G40: =COUNTIFS(Etapas!$D$2:$D$400,$A40,Etapas!$Q$2:$Q$400,G$38) -> 0 | H40: =COUNTIFS(Etapas!$D$2:$D$400,$A40,Etapas!$Q$2:$Q$400,H$38) -> 0 | I40: =COUNTIFS(Etapas!$D$2:$D$400,$A40,Etapas!$Q$2:$Q$400,I$38) -> 0 | J40: =COUNTIFS(Etapas!$D$2:$D$400,$A40,Etapas!$Q$2:$Q$400,J$38) -> 0 | ... M40: =COUNTIFS(Etapas!$D$2:$D$400,$A40,Etapas!$Q$2:$Q$400,M$38) -> 0 | N40: =IF(B40=0,0,(K40+L40+M40)/B40) -> 0.14285714
A41: 3. Diseño | B41: =COUNTIF(Etapas!$D$2:$D$400,$A41) -> 28 | C41: =COUNTIFS(Etapas!$D$2:$D$400,$A41,Etapas!$Q$2:$Q$400,C$38) -> 0 | D41: =COUNTIFS(Etapas!$D$2:$D$400,$A41,Etapas!$Q$2:$Q$400,D$38) -> 0 | E41: =COUNTIFS(Etapas!$D$2:$D$400,$A41,Etapas!$Q$2:$Q$400,E$38) -> 24 | F41: =COUNTIFS(Etapas!$D$2:$D$400,$A41,Etapas!$Q$2:$Q$400,F$38) -> 0 | G41: =COUNTIFS(Etapas!$D$2:$D$400,$A41,Etapas!$Q$2:$Q$400,G$38) -> 0 | H41: =COUNTIFS(Etapas!$D$2:$D$400,$A41,Etapas!$Q$2:$Q$400,H$38) -> 0 | I41: =COUNTIFS(Etapas!$D$2:$D$400,$A41,Etapas!$Q$2:$Q$400,I$38) -> 0 | J41: =COUNTIFS(Etapas!$D$2:$D$400,$A41,Etapas!$Q$2:$Q$400,J$38) -> 0 | ... M41: =COUNTIFS(Etapas!$D$2:$D$400,$A41,Etapas!$Q$2:$Q$400,M$38) -> 0 | N41: =IF(B41=0,0,(K41+L41+M41)/B41) -> 0.14285714
A42: 4. Planificación | B42: =COUNTIF(Etapas!$D$2:$D$400,$A42) -> 7 | C42: =COUNTIFS(Etapas!$D$2:$D$400,$A42,Etapas!$Q$2:$Q$400,C$38) -> 0 | D42: =COUNTIFS(Etapas!$D$2:$D$400,$A42,Etapas!$Q$2:$Q$400,D$38) -> 0 | E42: =COUNTIFS(Etapas!$D$2:$D$400,$A42,Etapas!$Q$2:$Q$400,E$38) -> 6 | F42: =COUNTIFS(Etapas!$D$2:$D$400,$A42,Etapas!$Q$2:$Q$400,F$38) -> 0 | G42: =COUNTIFS(Etapas!$D$2:$D$400,$A42,Etapas!$Q$2:$Q$400,G$38) -> 0 | H42: =COUNTIFS(Etapas!$D$2:$D$400,$A42,Etapas!$Q$2:$Q$400,H$38) -> 0 | I42: =COUNTIFS(Etapas!$D$2:$D$400,$A42,Etapas!$Q$2:$Q$400,I$38) -> 0 | J42: =COUNTIFS(Etapas!$D$2:$D$400,$A42,Etapas!$Q$2:$Q$400,J$38) -> 0 | ... M42: =COUNTIFS(Etapas!$D$2:$D$400,$A42,Etapas!$Q$2:$Q$400,M$38) -> 0 | N42: =IF(B42=0,0,(K42+L42+M42)/B42) -> 0.14285714
A43: 5. Construcción | B43: =COUNTIF(Etapas!$D$2:$D$400,$A43) -> 28 | C43: =COUNTIFS(Etapas!$D$2:$D$400,$A43,Etapas!$Q$2:$Q$400,C$38) -> 0 | D43: =COUNTIFS(Etapas!$D$2:$D$400,$A43,Etapas!$Q$2:$Q$400,D$38) -> 0 | E43: =COUNTIFS(Etapas!$D$2:$D$400,$A43,Etapas!$Q$2:$Q$400,E$38) -> 24 | F43: =COUNTIFS(Etapas!$D$2:$D$400,$A43,Etapas!$Q$2:$Q$400,F$38) -> 0 | G43: =COUNTIFS(Etapas!$D$2:$D$400,$A43,Etapas!$Q$2:$Q$400,G$38) -> 0 | H43: =COUNTIFS(Etapas!$D$2:$D$400,$A43,Etapas!$Q$2:$Q$400,H$38) -> 2 | I43: =COUNTIFS(Etapas!$D$2:$D$400,$A43,Etapas!$Q$2:$Q$400,I$38) -> 0 | J43: =COUNTIFS(Etapas!$D$2:$D$400,$A43,Etapas!$Q$2:$Q$400,J$38) -> 0 | ... M43: =COUNTIFS(Etapas!$D$2:$D$400,$A43,Etapas!$Q$2:$Q$400,M$38) -> 0 | N43: =IF(B43=0,0,(K43+L43+M43)/B43) -> 0.071428571
A44: 6. Validación | B44: =COUNTIF(Etapas!$D$2:$D$400,$A44) -> 42 | C44: =COUNTIFS(Etapas!$D$2:$D$400,$A44,Etapas!$Q$2:$Q$400,C$38) -> 0 | D44: =COUNTIFS(Etapas!$D$2:$D$400,$A44,Etapas!$Q$2:$Q$400,D$38) -> 0 | E44: =COUNTIFS(Etapas!$D$2:$D$400,$A44,Etapas!$Q$2:$Q$400,E$38) -> 42 | F44: =COUNTIFS(Etapas!$D$2:$D$400,$A44,Etapas!$Q$2:$Q$400,F$38) -> 0 | G44: =COUNTIFS(Etapas!$D$2:$D$400,$A44,Etapas!$Q$2:$Q$400,G$38) -> 0 | H44: =COUNTIFS(Etapas!$D$2:$D$400,$A44,Etapas!$Q$2:$Q$400,H$38) -> 0 | I44: =COUNTIFS(Etapas!$D$2:$D$400,$A44,Etapas!$Q$2:$Q$400,I$38) -> 0 | J44: =COUNTIFS(Etapas!$D$2:$D$400,$A44,Etapas!$Q$2:$Q$400,J$38) -> 0 | ... M44: =COUNTIFS(Etapas!$D$2:$D$400,$A44,Etapas!$Q$2:$Q$400,M$38) -> 0 | N44: =IF(B44=0,0,(K44+L44+M44)/B44) -> 0
A45: 7. Aseguramiento | B45: =COUNTIF(Etapas!$D$2:$D$400,$A45) -> 35 | C45: =COUNTIFS(Etapas!$D$2:$D$400,$A45,Etapas!$Q$2:$Q$400,C$38) -> 0 | D45: =COUNTIFS(Etapas!$D$2:$D$400,$A45,Etapas!$Q$2:$Q$400,D$38) -> 0 | E45: =COUNTIFS(Etapas!$D$2:$D$400,$A45,Etapas!$Q$2:$Q$400,E$38) -> 35 | F45: =COUNTIFS(Etapas!$D$2:$D$400,$A45,Etapas!$Q$2:$Q$400,F$38) -> 0 | G45: =COUNTIFS(Etapas!$D$2:$D$400,$A45,Etapas!$Q$2:$Q$400,G$38) -> 0 | H45: =COUNTIFS(Etapas!$D$2:$D$400,$A45,Etapas!$Q$2:$Q$400,H$38) -> 0 | I45: =COUNTIFS(Etapas!$D$2:$D$400,$A45,Etapas!$Q$2:$Q$400,I$38) -> 0 | J45: =COUNTIFS(Etapas!$D$2:$D$400,$A45,Etapas!$Q$2:$Q$400,J$38) -> 0 | ... M45: =COUNTIFS(Etapas!$D$2:$D$400,$A45,Etapas!$Q$2:$Q$400,M$38) -> 0 | N45: =IF(B45=0,0,(K45+L45+M45)/B45) -> 0
A46: 8. Adopción | B46: =COUNTIF(Etapas!$D$2:$D$400,$A46) -> 42 | C46: =COUNTIFS(Etapas!$D$2:$D$400,$A46,Etapas!$Q$2:$Q$400,C$38) -> 0 | D46: =COUNTIFS(Etapas!$D$2:$D$400,$A46,Etapas!$Q$2:$Q$400,D$38) -> 0 | E46: =COUNTIFS(Etapas!$D$2:$D$400,$A46,Etapas!$Q$2:$Q$400,E$38) -> 42 | F46: =COUNTIFS(Etapas!$D$2:$D$400,$A46,Etapas!$Q$2:$Q$400,F$38) -> 0 | G46: =COUNTIFS(Etapas!$D$2:$D$400,$A46,Etapas!$Q$2:$Q$400,G$38) -> 0 | H46: =COUNTIFS(Etapas!$D$2:$D$400,$A46,Etapas!$Q$2:$Q$400,H$38) -> 0 | I46: =COUNTIFS(Etapas!$D$2:$D$400,$A46,Etapas!$Q$2:$Q$400,I$38) -> 0 | J46: =COUNTIFS(Etapas!$D$2:$D$400,$A46,Etapas!$Q$2:$Q$400,J$38) -> 0 | ... M46: =COUNTIFS(Etapas!$D$2:$D$400,$A46,Etapas!$Q$2:$Q$400,M$38) -> 0 | N46: =IF(B46=0,0,(K46+L46+M46)/B46) -> 0
A47: 9. Operación | B47: =COUNTIF(Etapas!$D$2:$D$400,$A47) -> 21 | C47: =COUNTIFS(Etapas!$D$2:$D$400,$A47,Etapas!$Q$2:$Q$400,C$38) -> 0 | D47: =COUNTIFS(Etapas!$D$2:$D$400,$A47,Etapas!$Q$2:$Q$400,D$38) -> 0 | E47: =COUNTIFS(Etapas!$D$2:$D$400,$A47,Etapas!$Q$2:$Q$400,E$38) -> 21 | F47: =COUNTIFS(Etapas!$D$2:$D$400,$A47,Etapas!$Q$2:$Q$400,F$38) -> 0 | G47: =COUNTIFS(Etapas!$D$2:$D$400,$A47,Etapas!$Q$2:$Q$400,G$38) -> 0 | H47: =COUNTIFS(Etapas!$D$2:$D$400,$A47,Etapas!$Q$2:$Q$400,H$38) -> 0 | I47: =COUNTIFS(Etapas!$D$2:$D$400,$A47,Etapas!$Q$2:$Q$400,I$38) -> 0 | J47: =COUNTIFS(Etapas!$D$2:$D$400,$A47,Etapas!$Q$2:$Q$400,J$38) -> 0 | ... M47: =COUNTIFS(Etapas!$D$2:$D$400,$A47,Etapas!$Q$2:$Q$400,M$38) -> 0 | N47: =IF(B47=0,0,(K47+L47+M47)/B47) -> 0
A48: 10. Mejora Continua | B48: =COUNTIF(Etapas!$D$2:$D$400,$A48) -> 28 | C48: =COUNTIFS(Etapas!$D$2:$D$400,$A48,Etapas!$Q$2:$Q$400,C$38) -> 0 | D48: =COUNTIFS(Etapas!$D$2:$D$400,$A48,Etapas!$Q$2:$Q$400,D$38) -> 0 | E48: =COUNTIFS(Etapas!$D$2:$D$400,$A48,Etapas!$Q$2:$Q$400,E$38) -> 28 | F48: =COUNTIFS(Etapas!$D$2:$D$400,$A48,Etapas!$Q$2:$Q$400,F$38) -> 0 | G48: =COUNTIFS(Etapas!$D$2:$D$400,$A48,Etapas!$Q$2:$Q$400,G$38) -> 0 | H48: =COUNTIFS(Etapas!$D$2:$D$400,$A48,Etapas!$Q$2:$Q$400,H$38) -> 0 | I48: =COUNTIFS(Etapas!$D$2:$D$400,$A48,Etapas!$Q$2:$Q$400,I$38) -> 0 | J48: =COUNTIFS(Etapas!$D$2:$D$400,$A48,Etapas!$Q$2:$Q$400,J$38) -> 0 | ... M48: =COUNTIFS(Etapas!$D$2:$D$400,$A48,Etapas!$Q$2:$Q$400,M$38) -> 0 | N48: =IF(B48=0,0,(K48+L48+M48)/B48) -> 0
A51: Resumen por Componente / Subetapa
...

Sheet Etapas
A1: N° | B1: Módulo | C1: Fase | D1: Etapa | E1: Anterior | F1: Objetivo | G1: Componente/Subetapa | H1: Actividades/Tarea | I1: Productos/Entregables | J1: Criterios de Cumplimiento | K1: Responsable | L1: Punto de Control | M1: Fecha Inicio Programada | N1: Fecha Inicio Real | O1: Fecha Fin Máxima | P1: Fecha Fin Real | Q1: Estado
B2: AutoAtención | C2: I | D2: 1. Preparación | E2: Constitución Equipo de Trabajo | F2: Establecer las bases organizacionales, funcionales y técnicas necesarias para dar inicio al proyecto, definiendo la estructura de trabajo, los actores involucrados y el modelo de gobernanza. | G2: Constitución del equipo de Trabajo | H2: Designación de actores y responsabilidades | I2: Acta de Inicio | J2: Acta aprobada | K2: MINSAL | M2: 46023 | N2: 46023 | O2: 46053 | P2: 46053 | Q2: =IF(AND(M2="",N2="",O2="",P2=""),"COMPLETAR",IF(P2<>"",IF(O2="","Finalizado",IF(P2<O2,"Finalizado anticipado",IF(P2=O2,"Finalizado","Finalizado con desfase"))),IF(N2<>"",IF(O2="","No planificado",IF(O2<='Tablas y Glosario'!$F$1,"Atrasado",IF(M2="","En curso",IF(N2>M2,"Inicio retrasado",IF(N2<M2,"Inicio anticipado","En curso"))))),IF(M2="","COMPLETAR",IF('Tablas y Glosario'!$F$1>=M2,"No iniciado","Programado"))))) -> Finalizado
B3: AutoAtención | C3: I | D3: 1. Preparación | E3: Constitución Equipo de Trabajo | F3: Establecer las bases organizacionales, funcionales y técnicas necesarias para dar inicio al proyecto, definiendo la estructura de trabajo, los actores involucrados y el modelo de gobernanza. | G3: Definición de responsabilidades | H3: Descripción de Roles y matriz RACI | I3: Matriz RACI | J3: Matriz Aprobada | K3: MINSAL | M3: 46023 | N3: 46023 | O3: 46053 | P3: 46053 | Q3: =IF(AND(M3="",N3="",O3="",P3=""),"COMPLETAR",IF(P3<>"",IF(O3="","Finalizado",IF(P3<O3,"Finalizado anticipado",IF(P3=O3,"Finalizado","Finalizado con desfase"))),IF(N3<>"",IF(O3="","No planificado",IF(O3<='Tablas y Glosario'!$F$1,"Atrasado",IF(M3="","En curso",IF(N3>M3,"Inicio retrasado",IF(N3<M3,"Inicio anticipado","En curso"))))),IF(M3="","COMPLETAR",IF('Tablas y Glosario'!$F$1>=M3,"No iniciado","Programado"))))) -> Finalizado
B4: AutoAtención | C4: I | D4: 1. Preparación | E4: Constitución Equipo de Trabajo | F4: Establecer las bases organizacionales, funcionales y técnicas necesarias para dar inicio al proyecto, definiendo la estructura de trabajo, los actores involucrados y el modelo de gobernanza. | G4: Definición de mecanismos de seguimiento | H4: Definición de actividades y periodicidad | I4: Cronograma Inicial | J4: Cronograma aprobado | K4: MINSAL | M4: 46023 | N4: 46023 | O4: 46053 | P4: 46053 | Q4: =IF(AND(M4="",N4="",O4="",P4=""),"COMPLETAR",IF(P4<>"",IF(O4="","Finalizado",IF(P4<O4,"Finalizado anticipado",IF(P4=O4,"Finalizado","Finalizado con desfase"))),IF(N4<>"",IF(O4="","No planificado",IF(O4<='Tablas y Glosario'!$F$1,"Atrasado",IF(M4="","En curso",IF(N4>M4,"Inicio retrasado",IF(N4<M4,"Inicio anticipado","En curso"))))),IF(M4="","COMPLETAR",IF('Tablas y Glosario'!$F$1>=M4,"No iniciado","Programado"))))) -> Finalizado
B5: AutoAtención | C5: I | D5: 1. Preparación | E5: Constitución Equipo de Trabajo | F5: Establecer las bases organizacionales, funcionales y técnicas necesarias para dar inicio al proyecto, definiendo la estructura de trabajo, los actores involucrados y el modelo de gobernanza. | G5: Definición del alcance inicial | H5: Definición de objetivos, módulos, funcionalidades, integraciones, impacto | I5: Ficha de Alcance | J5: Ficha aprobada | K5: MINSAL | M5: 46023 | N5: 46023 | O5: 46053 | P5: 46053 | Q5: =IF(AND(M5="",N5="",O5="",P5=""),"COMPLETAR",IF(P5<>"",IF(O5="","Finalizado",IF(P5<O5,"Finalizado anticipado",IF(P5=O5,"Finalizado","Finalizado con desfase"))),IF(N5<>"",IF(O5="","No planificado",IF(O5<='Tablas y Glosario'!$F$1,"Atrasado",IF(M5="","En curso",IF(N5>M5,"Inicio retrasado",IF(N5<M5,"Inicio anticipado","En curso"))))),IF(M5="","COMPLETAR",IF('Tablas y Glosario'!$F$1>=M5,"No iniciado","Programado"))))) -> Finalizado
B6: AutoAtención | C6: I | D6: 2. Definición Funcional | E6: Levantamiento y definición | F6: Comprender la situación actual del módulo, identificar necesidades y definir los requerimientos funcionales que serán incorporados al proyecto. | G6: Análisis del estado actual (AS-IS) | H6: Levantamiento del proceso actual y su normativa | I6: Documento de análisis del estado actual | J6: Documento Aprobado | K6: MINSAL | M6: 46023 | N6: 46023 | O6: 46053 | P6: 46053 | Q6: =IF(AND(M6="",N6="",O6="",P6=""),"COMPLETAR",IF(P6<>"",IF(O6="","Finalizado",IF(P6<O6,"Finalizado anticipado",IF(P6=O6,"Finalizado","Finalizado con desfase"))),IF(N6<>"",IF(O6="","No planificado",IF(O6<='Tablas y Glosario'!$F$1,"Atrasado",IF(M6="","En curso",IF(N6>M6,"Inicio retrasado",IF(N6<M6,"Inicio anticipado","En curso"))))),IF(M6="","COMPLETAR",IF('Tablas y Glosario'!$F$1>=M6,"No iniciado","Programado"))))) -> Finalizado
B7: AutoAtención | C7: I | D7: 2. Definición Funcional | E7: Levantamiento y definición | F7: Comprender la situación actual del módulo, identificar necesidades del negocio y definir los requerimientos funcionales y técnicos que serán incorporados al proyecto. | G7: Definición de la solución futura TO-BE | H7: Levantamiento de requerimientos | I7: Documento de Requerimientos | J7: Documento Aprobado | K7: MINSAL | M7: 46023 | N7: 46023 | O7: 46053 | P7: 46053 | Q7: =IF(AND(M7="",N7="",O7="",P7=""),"COMPLETAR",IF(P7<>"",IF(O7="","Finalizado",IF(P7<O7,"Finalizado anticipado",IF(P7=O7,"Finalizado","Finalizado con desfase"))),IF(N7<>"",IF(O7="","No planificado",IF(O7<='Tablas y Glosario'!$F$1,"Atrasado",IF(M7="","En curso",IF(N7>M7,"Inicio retrasado",IF(N7<M7,"Inicio anticipado","En curso"))))),IF(M7="","COMPLETAR",IF('Tablas y Glosario'!$F$1>=M7,"No iniciado","Programado"))))) -> Finalizado
B8: AutoAtención | C8: I | D8: 2. Definición Funcional | E8: Levantamiento y definición | F8: Comprender la situación actual del módulo, identificar necesidades del negocio y definir los requerimientos funcionales y técnicos que serán incorporados al proyecto. | G8: Identificación de brechas | H8: Comparación | I8: Informe de Brechas | J8: Informe Aprobado | K8: MINSAL | M8: 46023 | N8: 46023 | O8: 46053 | P8: 46053 | Q8: =IF(AND(M8="",N8="",O8="",P8=""),"COMPLETAR",IF(P8<>"",IF(O8="","Finalizado",IF(P8<O8,"Finalizado anticipado",IF(P8=O8,"Finalizado","Finalizado con desfase"))),IF(N8<>"",IF(O8="","No planificado",IF(O8<='Tablas y Glosario'!$F$1,"Atrasado",IF(M8="","En curso",IF(N8>M8,"Inicio retrasado",IF(N8<M8,"Inicio anticipado","En curso"))))),IF(M8="","COMPLETAR",IF('Tablas y Glosario'!$F$1>=M8,"No iniciado","Programado"))))) -> Finalizado
B9: AutoAtención | C9: I | D9: 2. Definición Funcional | E9: Levantamiento y definición | F9: Comprender la situación actual del módulo, identificar necesidades del negocio y definir los requerimientos funcionales y técnicos que serán incorporados al proyecto. | G9: Definición y Priorización de Requerimientos (Backlog) | H9: Definir criterios y organizar requerimientos | I9: Registro priorizado de requerimientos (Product Backlog) | J9: Priorización aprobada | K9: MINSAL | M9: 46023 | N9: 46023 | O9: 46053 | P9: 46053 | Q9: =IF(AND(M9="",N9="",O9="",P9=""),"COMPLETAR",IF(P9<>"",IF(O9="","Finalizado",IF(P9<O9,"Finalizado anticipado",IF(P9=O9,"Finalizado","Finalizado con desfase"))),IF(N9<>"",IF(O9="","No planificado",IF(O9<='Tablas y Glosario'!$F$1,"Atrasado",IF(M9="","En curso",IF(N9>M9,"Inicio retrasado",IF(N9<M9,"Inicio anticipado","En curso"))))),IF(M9="","COMPLETAR",IF('Tablas y Glosario'!$F$1>=M9,"No iniciado","Programado"))))) -> Finalizado
B10: AutoAtención | C10: I | D10: 2. Definición Funcional | E10: Levantamiento y definición | F10: Comprender la situación actual del módulo, identificar necesidades del negocio y definir los requerimientos funcionales y técnicos que serán incorporados al proyecto. | G10: Definición de Requerimientos Funcionales | H10: Elaborar documento de requerimientos | I10: Documento A | J10: Documento A Aprobado | K10: MINSAL | M10: 46023 | N10: 46023 | O10: 46053 | P10: 46053 | Q10: =IF(AND(M10="",N10="",O10="",P10=""),"COMPLETAR",IF(P10<>"",IF(O10="","Finalizado",IF(P10<O10,"Finalizado anticipado",IF(P10=O10,"Finalizado","Finalizado con desfase"))),IF(N10<>"",IF(O10="","No planificado",IF(O10<='Tablas y Glosario'!$F$1,"Atrasado",IF(M10="","En curso",IF(N10>M10,"Inicio retrasado",IF(N10<M10,"Inicio anticipado","En curso"))))),IF(M10="","COMPLETAR",IF('Tablas y Glosario'!$F$1>=M10,"No iniciado","Programado"))))) -> Finalizado
B11: AutoAtención | C11: I | D11: 3. Diseño | E11: Análisis y Diseño | F11: Definir la solución funcional y técnica que dará respuesta a los requerimientos priorizados. | G11: Analisis funcional | H11: Generar Documento de estimación de esfuerzo | I11: Documento B | J11: Documento B Aprobado | K11: PROVEEDOR | M11: 46023 | N11: 46023 | O11: 46053 | P11: 46053 | Q11: =IF(AND(M11="",N11="",O11="",P11=""),"COMPLETAR",IF(P11<>"",IF(O11="","Finalizado",IF(P11<O11,"Finalizado anticipado",IF(P11=O11,"Finalizado","Finalizado con desfase"))),IF(N11<>"",IF(O11="","No planificado",IF(O11<='Tablas y Glosario'!$F$1,"Atrasado",IF(M11="","En curso",IF(N11>M11,"Inicio retrasado",IF(N11<M11,"Inicio anticipado","En curso"))))),IF(M11="","COMPLETAR",IF('Tablas y Glosario'!$F$1>=M11,"No iniciado","Programado"))))) -> Finalizado
B12: AutoAtención | C12: I | D12: 3. Diseño | E12: Análisis y Diseño | F12: Definir la solución funcional y técnica que dará respuesta a los requerimientos priorizados. | G12: Validación estimación de esfuerzos | H12: Revisión estimación de esfuerzos | I12: Aprobación | J12: Documento B Aprobado | K12: MINSAL | M12: 46023 | N12: 46023 | O12: 46053 | P12: 46053 | Q12: =IF(AND(M12="",N12="",O12="",P12=""),"COMPLETAR",IF(P12<>"",IF(O12="","Finalizado",IF(P12<O12,"Finalizado anticipado",IF(P12=O12,"Finalizado","Finalizado con desfase"))),IF(N12<>"",IF(O12="","No planificado",IF(O12<='Tablas y Glosario'!$F$1,"Atrasado",IF(M12="","En curso",IF(N12>M12,"Inicio retrasado",IF(N12<M12,"Inicio anticipado","En curso"))))),IF(M12="","COMPLETAR",IF('Tablas y Glosario'!$F$1>=M12,"No iniciado","Programado"))))) -> Finalizado
B13: AutoAtención | C13: I | D13: 3. Diseño | E13: Análisis y Diseño | F13: Definir la solución funcional y técnica que dará respuesta a los requerimientos priorizados. | G13: Diseño de la solución | H13: Generar Prototipos y Maquetas | I13: Documento C | J13: Documento C Aprobado | K13: PROVEEDOR | M13: 46023 | N13: 46023 | O13: 46053 | P13: 46053 | Q13: =IF(AND(M13="",N13="",O13="",P13=""),"COMPLETAR",IF(P13<>"",IF(O13="","Finalizado",IF(P13<O13,"Finalizado anticipado",IF(P13=O13,"Finalizado","Finalizado con desfase"))),IF(N13<>"",IF(O13="","No planificado",IF(O13<='Tablas y Glosario'!$F$1,"Atrasado",IF(M13="","En curso",IF(N13>M13,"Inicio retrasado",IF(N13<M13,"Inicio anticipado","En curso"))))),IF(M13="","COMPLETAR",IF('Tablas y Glosario'!$F$1>=M13,"No iniciado","Programado"))))) -> Finalizado
... B17: AutoAtención | C17: I | D17: 5. Construcción | E17: Construcción | F17: Desarrollar y configurar las funcionalidades requeridas. | G17: Configuración. | H17: Configuración de componentes | I17: Código fuente. | J17: Componentes aprobados | K17: PROVEEDOR | M17: 46023 | N17: 46023 | O17: 46053 | P17: 46053 | Q17: =IF(AND(M17="",N17="",O17="",P17=""),"COMPLETAR",IF(P17<>"",IF(O17="","Finalizado",IF(P17<O17,"Finalizado anticipado",IF(P17=O17,"Finalizado","Finalizado con desfase"))),IF(N17<>"",IF(O17="","No planificado",IF(O17<='Tablas y Glosario'!$F$1,"Atrasado",IF(M17="","En curso",IF(N17>M17,"Inicio retrasado",IF(N17<M17,"Inicio anticipado","En curso"))))),IF(M17="","COMPLETAR",IF('Tablas y Glosario'!$F$1>=M17,"No iniciado","Programado"))))) -> Finalizado
B18: AutoAtención | C18: I | D18: 5. Construcción | E18: Construcción | F18: Desarrollar y configurar las funcionalidades requeridas. | G18: Integraciones. | H18: Desarrollo de integraciones | I18: Integraciones desarrolladas | J18: Integraciones aprobadas | K18: PROVEEDOR | M18: 46054 | N18: 46054 | O18: 46234 | Q18: =IF(AND(M18="",N18="",O18="",P18=""),"COMPLETAR",IF(P18<>"",IF(O18="","Finalizado",IF(P18<O18,"Finalizado anticipado",IF(P18=O18,"Finalizado","Finalizado con desfase"))),IF(N18<>"",IF(O18="","No planificado",IF(O18<='Tablas y Glosario'!$F$1,"Atrasado",IF(M18="","En curso",IF(N18>M18,"Inicio retrasado",IF(N18<M18,"Inicio anticipado","En curso"))))),IF(M18="","COMPLETAR",IF('Tablas y Glosario'!$F$1>=M18,"No iniciado","Programado"))))) -> En curso
B19: AutoAtención | C19: I | D19: 5. Construcción | E19: Construcción | F19: Desarrollar y configurar las funcionalidades requeridas. | G19: Pruebas unitarias. | H19: Realización de pruebas | I19: Registro de pruebas unitarias. | J19: Pruebas aprobadas | K19: PROVEEDOR | M19: 46054 | N19: 46054 | O19: 46265 | Q19: =IF(AND(M19="",N19="",O19="",P19=""),"COMPLETAR",IF(P19<>"",IF(O19="","Finalizado",IF(P19<O19,"Finalizado anticipado",IF(P19=O19,"Finalizado","Finalizado con desfase"))),IF(N19<>"",IF(O19="","No planificado",IF(O19<='Tablas y Glosario'!$F$1,"Atrasado",IF(M19="","En curso",IF(N19>M19,"Inicio retrasado",IF(N19<M19,"Inicio anticipado","En curso"))))),IF(M19="","COMPLETAR",IF('Tablas y Glosario'!$F$1>=M19,"No iniciado","Programado"))))) -> En curso
B20: AutoAtención | C20: I | D20: 6. Validación | E20: Certificación | F20: Validar que la solución cumple con los requerimientos funcionales y técnicos definidos. | G20: Definición de Pilotos | H20: Definir organismos que realizaran las pruebas | I20: Nómina de organismos piloto | J20: Solución certificada. | K20: MINSAL | M20: 46266 | Q20: =IF(AND(M20="",N20="",O20="",P20=""),"COMPLETAR",IF(P20<>"",IF(O20="","Finalizado",IF(P20<O20,"Finalizado anticipado",IF(P20=O20,"Finalizado","Finalizado con desfase"))),IF(N20<>"",IF(O20="","No planificado",IF(O20<='Tablas y Glosario'!$F$1,"Atrasado",IF(M20="","En curso",IF(N20>M20,"Inicio retrasado",IF(N20<M20,"Inicio anticipado","En curso"))))),IF(M20="","COMPLETAR",IF('Tablas y Glosario'!$F$1>=M20,"No iniciado","Programado"))))) -> Programado
B21: AutoAtención | C21: I | D21: 6. Validación | E21: Certificación | F21: Validar que la solución cumple con los requerimientos funcionales y técnicos definidos. | G21: Validación funcional (pruebas) | H21: Realización y validación de pruebas | I21: Plan de pruebas realizadas | J21: Plan de pruebas aprobadas | K21: MINSAL | M21: 46267 | Q21: =IF(AND(M21="",N21="",O21="",P21=""),"COMPLETAR",IF(P21<>"",IF(O21="","Finalizado",IF(P21<O21,"Finalizado anticipado",IF(P21=O21,"Finalizado","Finalizado con desfase"))),IF(N21<>"",IF(O21="","No planificado",IF(O21<='Tablas y Glosario'!$F$1,"Atrasado",IF(M21="","En curso",IF(N21>M21,"Inicio retrasado",IF(N21<M21,"Inicio anticipado","En curso"))))),IF(M21="","COMPLETAR",IF('Tablas y Glosario'!$F$1>=M21,"No iniciado","Programado"))))) -> Programado
B22: AutoAtención | C22: I | D22: 6. Validación | E22: Certificación | F22: Validar que la solución cumple con los requerimientos funcionales y técnicos definidos. | G22: Retroalimentación | H22: Gestión de observaciones. | I22: Incidencias | J22: Incidencias Resueltas | K22: PROVEEDOR | M22: 46268 | Q22: =IF(AND(M22="",N22="",O22="",P22=""),"COMPLETAR",IF(P22<>"",IF(O22="","Finalizado",IF(P22<O22,"Finalizado anticipado",IF(P22=O22,"Finalizado","Finalizado con desfase"))),IF(N22<>"",IF(O22="","No planificado",IF(O22<='Tablas y Glosario'!$F$1,"Atrasado",IF(M22="","En curso",IF(N22>M22,"Inicio retrasado",IF(N22<M22,"Inicio anticipado","En curso"))))),IF(M22="","COMPLETAR",IF('Tablas y Glosario'!$F$1>=M22,"No iniciado","Programado"))))) -> Programado
B23: AutoAtención | C23: I | D23: 6. Validación | E23: Certificación | F23: Validar que la solución cumple con los requerimientos funcionales y técnicos definidos. | G23: Corrección | H23: Actualizar solución desarrollada | I23: Solución actualizada | J23: Solución Aprobada | K23: PROVEEDOR | M23: 46269 | Q23: =IF(AND(M23="",N23="",O23="",P23=""),"COMPLETAR",IF(P23<>"",IF(O23="","Finalizado",IF(P23<O23,"Finalizado anticipado",IF(P23=O23,"Finalizado","Finalizado con desfase"))),IF(N23<>"",IF(O23="","No planificado",IF(O23<='Tablas y Glosario'!$F$1,"Atrasado",IF(M23="","En curso",IF(N23>M23,"Inicio retrasado",IF(N23<M23,"Inicio anticipado","En curso"))))),IF(M23="","COMPLETAR",IF('Tablas y Glosario'!$F$1>=M23,"No iniciado","Programado"))))) -> Programado
B24: AutoAtención | C24: I | D24: 6. Validación | E24: Certificación | F24: Validar que la solución cumple con los requerimientos funcionales y técnicos definidos. | G24: Revalidación | H24: Realización y validación de pruebas | I24: Cierre de incidencias | J24: Cierre ejecutado | K24: MINSAL | M24: 46270 | Q24: =IF(AND(M24="",N24="",O24="",P24=""),"COMPLETAR",IF(P24<>"",IF(O24="","Finalizado",IF(P24<O24,"Finalizado anticipado",IF(P24=O24,"Finalizado","Finalizado con desfase"))),IF(N24<>"",IF(O24="","No planificado",IF(O24<='Tablas y Glosario'!$F$1,"Atrasado",IF(M24="","En curso",IF(N24>M24,"Inicio retrasado",IF(N24<M24,"Inicio anticipado","En curso"))))),IF(M24="","COMPLETAR",IF('Tablas y Glosario'!$F$1>=M24,"No iniciado","Programado"))))) -> Programado
B25: AutoAtención | C25: I | D25: 6. Validación | E25: Certificación | F25: Validar que la solución cumple con los requerimientos funcionales y técnicos definidos. | G25: Aprobación | H25: Validar funcionalmente | I25: Certificado de aprobación de pruebas | J25: Certificación entregada | K25: MINSAL | M25: 46271 | Q25: =IF(AND(M25="",N25="",O25="",P25=""),"COMPLETAR",IF(P25<>"",IF(O25="","Finalizado",IF(P25<O25,"Finalizado anticipado",IF(P25=O25,"Finalizado","Finalizado con desfase"))),IF(N25<>"",IF(O25="","No planificado",IF(O25<='Tablas y Glosario'!$F$1,"Atrasado",IF(M25="","En curso",IF(N25>M25,"Inicio retrasado",IF(N25<M25,"Inicio anticipado","En curso"))))),IF(M25="","COMPLETAR",IF('Tablas y Glosario'!$F$1>=M25,"No iniciado","Programado"))))) -> Programado
B26: AutoAtención | C26: I | D26: 7. Aseguramiento | E26: Seguridad e Infraestructura | F26: Garantizar que la solución cumpla con los estándares de seguridad y cuente con la infraestructura necesaria para su operación. | G26: Seguridad. | H26: Ejecución Análisis de vulnerabilidades. | I26: Informe de hallazgos | J26: Certificación de seguridad | K26: MINSAL | M26: 46272 | Q26: =IF(AND(M26="",N26="",O26="",P26=""),"COMPLETAR",IF(P26<>"",IF(O26="","Finalizado",IF(P26<O26,"Finalizado anticipado",IF(P26=O26,"Finalizado","Finalizado con desfase"))),IF(N26<>"",IF(O26="","No planificado",IF(O26<='Tablas y Glosario'!$F$1,"Atrasado",IF(M26="","En curso",IF(N26>M26,"Inicio retrasado",IF(N26<M26,"Inicio anticipado","En curso"))))),IF(M26="","COMPLETAR",IF('Tablas y Glosario'!$F$1>=M26,"No iniciado","Programado"))))) -> Programado
B27: AutoAtención | C27: I | D27: 7. Aseguramiento | E27: Seguridad e Infraestructura | F27: Garantizar que la solución cumpla con los estándares de seguridad y cuente con la infraestructura necesaria para su operación. | G27: Infraestructura. | H27: Configuración de ambientes, servidores y redes | I27: Infraestructura habilitada | J27: Certificación de infraestructura | K27: PROVEEDOR | M27: 46273 | Q27: =IF(AND(M27="",N27="",O27="",P27=""),"COMPLETAR",IF(P27<>"",IF(O27="","Finalizado",IF(P27<O27,"Finalizado anticipado",IF(P27=O27,"Finalizado","Finalizado con desfase"))),IF(N27<>"",IF(O27="","No planificado",IF(O27<='Tablas y Glosario'!$F$1,"Atrasado",IF(M27="","En curso",IF(N27>M27,"Inicio retrasado",IF(N27<M27,"Inicio anticipado","En curso"))))),IF(M27="","COMPLETAR",IF('Tablas y Glosario'!$F$1>=M27,"No iniciado","Programado"))))) -> Programado
B28: AutoAtención | C28: I | D28: 7. Aseguramiento | E28: Seguridad e Infraestructura | F28: Garantizar que la solución cumpla con los estándares de seguridad y cuente con la infraestructura necesaria para su operación. | G28: Rendimiento. | H28: Ejecución de pruebas de estrés | I28: Informe de rendimiento | J28: Certificación de rendimiento | K28: PROVEEDOR | M28: 46274 | Q28: =IF(AND(M28="",N28="",O28="",P28=""),"COMPLETAR",IF(P28<>"",IF(O28="","Finalizado",IF(P28<O28,"Finalizado anticipado",IF(P28=O28,"Finalizado","Finalizado con desfase"))),IF(N28<>"",IF(O28="","No planificado",IF(O28<='Tablas y Glosario'!$F$1,"Atrasado",IF(M28="","En curso",IF(N28>M28,"Inicio retrasado",IF(N28<M28,"Inicio anticipado","En curso"))))),IF(M28="","COMPLETAR",IF('Tablas y Glosario'!$F$1>=M28,"No iniciado","Programado"))))) -> Programado
B29: AutoAtención | C29: I | D29: 7. Aseguramiento | E29: Seguridad e Infraestructura | F29: Garantizar que la solución cumpla con los estándares de seguridad y cuente con la infraestructura necesaria para su operación. | G29: Integraciones. | H29: Validación de servicios de integración | I29: Informe del estado de integraciones | J29: Certificación de integraciones | K29: PROVEEDOR | M29: 46275 | Q29: =IF(AND(M29="",N29="",O29="",P29=""),"COMPLETAR",IF(P29<>"",IF(O29="","Finalizado",IF(P29<O29,"Finalizado anticipado",IF(P29=O29,"Finalizado","Finalizado con desfase"))),IF(N29<>"",IF(O29="","No planificado",IF(O29<='Tablas y Glosario'!$F$1,"Atrasado",IF(M29="","En curso",IF(N29>M29,"Inicio retrasado",IF(N29<M29,"Inicio anticipado","En curso"))))),IF(M29="","COMPLETAR",IF('Tablas y Glosario'!$F$1>=M29,"No iniciado","Programado"))))) -> Programado
B30: AutoAtención | C30: I | D30: 7. Aseguramiento | E30: Seguridad e Infraestructura | F30: Garantizar que la solución cumpla con los estándares de seguridad y cuente con la infraestructura necesaria para su operación. | G30: Preparación Operacional | H30: Verificar respaldos, usuarios, perfiles, permisos | I30: Check List Operacional | J30: Certificación de Operación | K30: MINSAL | M30: 46276 | Q30: =IF(AND(M30="",N30="",O30="",P30=""),"COMPLETAR",IF(P30<>"",IF(O30="","Finalizado",IF(P30<O30,"Finalizado anticipado",IF(P30=O30,"Finalizado","Finalizado con desfase"))),IF(N30<>"",IF(O30="","No planificado",IF(O30<='Tablas y Glosario'!$F$1,"Atrasado",IF(M30="","En curso",IF(N30>M30,"Inicio retrasado",IF(N30<M30,"Inicio anticipado","En curso"))))),IF(M30="","COMPLETAR",IF('Tablas y Glosario'!$F$1>=M30,"No iniciado","Programado"))))) -> Programado
B31: AutoAtención | C31: I | D31: 8. Adopción | E31: Despliegue y Gestión del Cambio | F31: Preparar a la organización para la adopción del nuevo módulo y ejecutar su despliegue de manera planificada. | G31: Preparación | H31: Elaboración del plan de adopción | I31: Plan de Gestión del Cambio. | J31: Plan de GDC aprobado | K31: PROVEEDOR | M31: 46277 | Q31: =IF(AND(M31="",N31="",O31="",P31=""),"COMPLETAR",IF(P31<>"",IF(O31="","Finalizado",IF(P31<O31,"Finalizado anticipado",IF(P31=O31,"Finalizado","Finalizado con desfase"))),IF(N31<>"",IF(O31="","No planificado",IF(O31<='Tablas y Glosario'!$F$1,"Atrasado",IF(M31="","En curso",IF(N31>M31,"Inicio retrasado",IF(N31<M31,"Inicio anticipado","En curso"))))),IF(M31="","COMPLETAR",IF('Tablas y Glosario'!$F$1>=M31,"No iniciado","Programado"))))) -> Programado
... B295: Portal SIRH | C295: I | D295: 10. Mejora Continua | E295: Evaluación y Mejora Continua | F295: Evaluar los resultados de la implementación, identificar oportunidades de mejora y retroalimentar el proceso de evolución continua del módulo. | G295: Planificación Evolutiva | H295: Categorización y priorización de mejoras | I295: Documento A Replanificación | J295: Documento A aprobado | K295: MINSAL | M295: 46541 | Q295: =IF(AND(M295="",N295="",O295="",P295=""),"COMPLETAR",IF(P295<>"",IF(O295="","Finalizado",IF(P295<O295,"Finalizado anticipado",IF(P295=O295,"Finalizado","Finalizado con desfase"))),IF(N295<>"",IF(O295="","No planificado",IF(O295<='Tablas y Glosario'!$F$1,"Atrasado",IF(M295="","En curso",IF(N295>M295,"Inicio retrasado",IF(N295<M295,"Inicio anticipado","En curso"))))),IF(M295="","COMPLETAR",IF('Tablas y Glosario'!$F$1>=M295,"No iniciado","Programado"))))) -> Programado

Sheet Req. AutoAtención
A1: id | B1: Tema | C1: Fase | D1: Id Requerimiento | E1: Descripcion segun Bases de Licitación | F1: Especificación Equipo SIRH | G1: Implementado | H1: Requiere requerimiento | I1: Fecha solicitud de Entrega (Indra) | J1: Fecha de entrega requerimiento | K1: Medio de Entrega | L1: Estado | M1: Acción necesaria | N1: Responsable
A2: 6 | B2: ANTECEDENTES DEL FUNCIONARIO | C2: I | D2: APE-03-01 | E2: Realizar la verificación y actualización de los datos personales, académicos, laborales u otros datos relevantes de la hoja de vida del trabajador, a su vez, deberá permitir adjuntar la documentación de respaldo correspondiente para posterior visación del analista de personal. | F2: Requerimiento se basa en las funcionalidades actuales disponibles | G2: Si | H2: No | J2: Inicial | K2: Reuniones - Oferta técnica | L2: Listo | M2: Revisar | N2: SIRH - Piloto
A3: 7 | B3: ANTECEDENTES DEL FUNCIONARIO | C3: I | D3: APE-03-02 | E3: Realizar descarga de certificados de la hoja de vida del trabajador, dichos certificados son: | F3: Requerimiento se basa en las funcionalidades actuales disponibles | G3: x | H3: x | J3: Inicial | K3: Reuniones - Oferta técnica | L3: Listo | M3: Revisar | N3: SIRH - Piloto
A4: 8 | B4: ANTECEDENTES DEL FUNCIONARIO | C4: I | D4: APE-03-02 | E4: Calificaciones | F4: Requerimiento se basa en las funcionalidades actuales disponibles | G4: Si | H4: No | J4: Inicial | K4: Reuniones - Oferta técnica | L4: Listo | M4: Revisar | N4: SIRH - Piloto
A5: 9 | B5: ANTECEDENTES DEL FUNCIONARIO | C5: I | D5: APE-03-02 | E5: Capacitaciones | F5: Requerimiento se basa en las funcionalidades actuales disponibles | G5: Si | H5: No | J5: Inicial | K5: Reuniones - Oferta técnica | L5: Listo | M5: Revisar | N5: SIRH - Piloto
A6: 10 | B6: ANTECEDENTES DEL FUNCIONARIO | C6: I | D6: APE-03-02 | E6: Relación de servicios | F6: Requerimiento se basa en las funcionalidades actuales disponibles | G6: Si | H6: No | J6: Inicial | K6: Reuniones - Oferta técnica | L6: Listo | M6: Revisar | N6: SIRH - Piloto
A7: 11 | B7: ANTECEDENTES DEL FUNCIONARIO | C7: I | D7: APE-03-02 | E7: Cargas familiares registradas | F7: Requerimiento se basa en las funcionalidades actuales disponibles | G7: Si | H7: No | J7: Inicial | K7: Reuniones - Oferta técnica | L7: Listo | M7: Revisar | N7: SIRH - Piloto
A8: 12 | B8: ANTECEDENTES DEL FUNCIONARIO | C8: I | D8: APE-03-02 | E8: Antigüedad laboral (analizar los parámetros que se necesitan para la emisión de este certificado) | F8: Requerimiento se basa en las funcionalidades actuales disponibles | G8: Si | H8: No | J8: Inicial | K8: Reuniones - Oferta técnica | L8: Listo | M8: Revisar | N8: SIRH - Piloto
A9: 13 | B9: ANTECEDENTES DEL FUNCIONARIO | C9: I | D9: APE-03-02 | E9: Anotaciones de Merito y Demerito | F9: Requerimiento se fundamenta en las Bases de Licitación | G9: No | H9: No | J9: Secuencia | K9: Bases de Licitación | L9: Listo | M9: Implementar | N9: SIRH - Piloto | O9: No he podido visualizar mis anotaciones. Falta filtro de fecha
A10: 14 | B10: ANTECEDENTES DEL FUNCIONARIO | C10: I | D10: APE-03-02 | E10: Rentas por Empleador (operación renta) | F10: Requerimiento se basa en las funcionalidades actuales disponibles | G10: Si | H10: No | J10: Inicial | K10: Reuniones - Oferta técnica | L10: Listo | M10: Revisar | N10: SIRH - Piloto
A11: 15 | B11: ANTECEDENTES DEL FUNCIONARIO | C11: I | D11: APE-03-02 | E11: Sueldo, certificado de sueldo | F11: Requerimiento se basa en las funcionalidades actuales disponibles | G11: Si | H11: No | J11: Inicial | K11: Reuniones - Oferta técnica | L11: Listo | M11: Revisar | N11: SIRH - Piloto
A12: 16 | B12: ANTECEDENTES DEL FUNCIONARIO | C12: I | D12: APE-03-03 | E12: Consultar las Liquidaciones de sueldo por rango de fechas, dando la opción de descargarlas. | F12: Requerimiento se basa en las funcionalidades actuales disponibles | G12: Si | H12: No | J12: Inicial | K12: Reuniones - Oferta técnica | L12: Listo | M12: Revisar | N12: SIRH - Piloto
A13: 20 | B13: CONTROL DE ASISTENCIA Y AUSENTISMO | C13: I | D13: APE-04-03 | E13: Solicitar y registrar al menos los siguientes ausentismos: | F13: Requerimiento se basa en las funcionalidades actuales disponibles | G13: SI | H13: No | J13: Inicial | K13: Reuniones - Oferta técnica | L13: Listo | M13: Revisar | N13: SIRH - Piloto
A14: 21 | B14: CONTROL DE ASISTENCIA Y AUSENTISMO | C14: I | D14: APE-04-03 | E14: Permisos Administrativos | F14: Requerimiento se basa en las funcionalidades actuales disponibles | G14: Si | H14: No | J14: Inicial | K14: Reuniones - Oferta técnica | L14: Listo | M14: Revisar | N14: SIRH - Piloto
A15: 22 | B15: CONTROL DE ASISTENCIA Y AUSENTISMO | C15: I | D15: APE-04-03 | E15: Feriados Legales | F15: Requerimiento se basa en las funcionalidades actuales disponibles | G15: Si | H15: No | J15: Inicial | K15: Reuniones - Oferta técnica | L15: Listo | M15: Revisar | N15: SIRH - Piloto
A16: 23 | B16: CONTROL DE ASISTENCIA Y AUSENTISMO | C16: I | D16: APE-04-03 | E16: Descansos Complementarios | F16: Requerimiento se basa en las funcionalidades actuales disponibles | G16: Si | H16: No | J16: Inicial | K16: Reuniones - Oferta técnica | L16: Listo | M16: Revisar | N16: SIRH - Piloto
A17: 24 | B17: CONTROL DE ASISTENCIA Y AUSENTISMO | C17: I | D17: APE-04-03 | E17: Permisos Sin Goce de Sueldo | F17: Requerimiento se basa en la estructura de solicitudes ya definida en las funcionalidades actuales | G17: No | H17: No | J17: Secuencia | K17: Reuniones | L17: Listo | M17: Implementar | N17: Indra
A18: 26 | B18: CONTROL DE ASISTENCIA Y AUSENTISMO | C18: I | D18: APE-04-03 | E18: Permiso Paternal | F18: Requerimiento se basa en la estructura de solicitudes ya definida en las funcionalidades actuales | G18: No | H18: No | J18: Secuencia | K18: Reuniones | L18: Listo | M18: Implementar | N18: Indra
A19: 27 | B19: CONTROL DE ASISTENCIA Y AUSENTISMO | C19: I | D19: APE-04-03 | E19: Permiso por Matrimonio o acuerdo unión civil | F19: Requerimiento se basa en la estructura de solicitudes ya definida en las funcionalidades actuales | G19: No | H19: No | J19: Secuencia | K19: Reuniones | L19: Pendiente | M19: Implementar | N19: Indra | O19: No he podido visualizarlo
A20: 28 | B20: CONTROL DE ASISTENCIA Y AUSENTISMO | C20: I | D20: APE-04-03 | E20: Permiso gremial | F20: Requerimiento se basa en la estructura de solicitudes ya definida en las funcionalidades actuales | G20: No | H20: No | J20: Secuencia | K20: Reuniones | L20: Listo | M20: Implementar | N20: Indra
A21: 29 | B21: CONTROL DE ASISTENCIA Y AUSENTISMO | C21: I | D21: APE-04-03 | E21: Permiso entre Feriados | F21: Requerimiento se basa en la estructura de solicitudes ya definida en las funcionalidades actuales | G21: No | H21: No | J21: Secuencia | K21: Reuniones | L21: Listo | M21: Implementar | N21: Indra
A22: 30 | B22: CONTROL DE ASISTENCIA Y AUSENTISMO | C22: I | D22: APE-04-03 | E22: Fallecimiento cónyuge | F22: Requerimiento se basa en la estructura de solicitudes ya definida en las funcionalidades actuales | G22: No | H22: No | J22: Secuencia | K22: Reuniones | L22: Listo | M22: Implementar | N22: Indra
A23: 31 | B23: CONTROL DE ASISTENCIA Y AUSENTISMO | C23: I | D23: APE-04-03 | E23: Fallecimiento hijo | F23: Requerimiento se basa en la estructura de solicitudes ya definida en las funcionalidades actuales | G23: No | H23: No | J23: Secuencia | K23: Reuniones | L23: Listo | M23: Implementar | N23: Indra
A24: 32 | B24: CONTROL DE ASISTENCIA Y AUSENTISMO | C24: I | D24: APE-04-03 | E24: Fallecimiento padre o madre | F24: Requerimiento se basa en la estructura de solicitudes ya definida en las funcionalidades actuales | G24: No | H24: No | J24: Secuencia | K24: Reuniones | L24: Listo | M24: Implementar | N24: Indra
A25: 33 | B25: CONTROL DE ASISTENCIA Y AUSENTISMO | C25: I | D25: APE-04-03 | E25: Fallecimiento hijo en gestación | F25: Requerimiento se basa en la estructura de solicitudes ya definida en las funcionalidades actuales | G25: No | H25: No | J25: Secuencia | K25: Reuniones | L25: Listo | M25: Implementar | N25: Indra
A26: 34 | B26: CONTROL DE ASISTENCIA Y AUSENTISMO | C26: I | D26: APE-04-03 | E26: Permiso bombero | F26: Requerimiento se basa en la estructura de solicitudes ya definida en las funcionalidades actuales | G26: No | H26: No | J26: Secuencia | K26: Reuniones | L26: Listo | M26: Implementar | N26: Indra
A27: 35 | B27: CONTROL DE ASISTENCIA Y AUSENTISMO | C27: I | D27: APE-04-03 | E27: Permiso deportivo | F27: Requerimiento se basa en la estructura de solicitudes ya definida en las funcionalidades actuales | G27: No | H27: No | J27: Secuencia | K27: Reuniones | L27: Listo | M27: Implementar | N27: Indra
A28: 36 | B28: CONTROL DE ASISTENCIA Y AUSENTISMO | C28: I | D28: APE-04-03 | E28: Permiso lactancia | F28: Requerimiento se basa en la estructura de solicitudes ya definida en las funcionalidades actuales | G28: No | H28: No | J28: Secuencia | K28: Reuniones | L28: Pendiente | M28: Implementar | N28: Indra | O28: No he podido visualizarlo
A29: 37 | B29: CONTROL DE ASISTENCIA Y AUSENTISMO | C29: I | D29: APE-04-03 | E29: Descanso compensatorio | F29: Requerimiento se basa en la estructura de solicitudes ya definida en las funcionalidades actuales | G29: No | H29: No | J29: Secuencia | K29: Reuniones | L29: Pendiente | M29: Implementar | N29: Indra | O29: No he podido visualizarlo
A30: 38 | B30: CONTROL DE ASISTENCIA Y AUSENTISMO | C30: I | D30: APE-04-03 | E30: Permiso por Alerta Sanitaria | F30: Requerimiento se basa en la estructura de solicitudes ya definida en las funcionalidades actuales | G30: No | H30: No | J30: Secuencia | K30: Reuniones | L30: Listo | M30: Implementar | N30: Indra
A31: 39 | B31: CONTROL DE ASISTENCIA Y AUSENTISMO | C31: I | D31: APE-04-03 | E31: Decreto Excepcion (Agregado) | F31: Requerimiento se basa en la estructura de solicitudes ya definida en las funcionalidades actuales | G31: No | H31: No | J31: Secuencia | K31: Reuniones | L31: Pendiente | M31: Implementar | N31: Indra
A32: 40 | B32: CONTROL DE ASISTENCIA Y AUSENTISMO | C32: I | D32: APE-04-04 | E32: Mostrar los saldos disponibles para los permisos, administrativos, feriados legales y descansos complementarios, para este último, el sistema deberá entregar una alerta de al menos 2 meses antes de cumplir el vencimiento de horas, asimismo informar el comienzo del proceso de acumulación de los feriados legales, indicando el total de días que pueden y no traspasar. | F32: •Vencimiento de horas: debe comenzar a mostrarse con a lo menos 2 meses de anticipación al vencimiento y corresponde a algún mensaje llamativo en la vista inicial al usuario (Resumen), además de la notificación. •Proceso de Acumulación de FL: Corresponde a mensaje llamativo en la vista inicial al usuario (Resumen) desde que se habilita el proceso, además de la notificación. | G32: Si | H32: No | J32: 46157 | K32: Correo | L32: Maqueta | M32: Implementar | N32: Indra | O32: Pendiente carga de FL y horas por vencer
A33: 41 | B33: CONTROL DE ASISTENCIA Y AUSENTISMO | C33: I | D33: APE-04-04 | E33: Alerta de horas en en resumen de saldos y liquidaciones | F33: Se refiere a resumen funcional de horas por vencer mediante mensaje dentro del aplicativo, en la vista resumen | G33: No | H33: Si | I33: 46142 | J33: Inicial | K33: Reuniones - Oferta técnica | L33: Maqueta | M33: Implementar | N33: Indra
A34: 42 | B34: CONTROL DE ASISTENCIA Y AUSENTISMO | C34: I | D34: APE-04-05 | E34: Realizar el proceso de acumulación de feriado legal. | F34: Requerimiento se basa en las funcionalidades actuales disponibles | G34: Si | H34: No | J34: Inicial | K34: Reuniones - Oferta técnica | L34: Listo | M34: Revisar | N34: SIRH - Piloto
A35: 43 | B35: CONTROL DE ASISTENCIA Y AUSENTISMO | C35: I | D35: APE-04-06 | E35: Mostrar el histórico de solicitudes por tipo de ausentismos, mostrando el detalle de las solicitudes y estado, dicho estado deberá indicar por cuál de los firmantes se encuentra pendiente, si la solicitud se encuentra correctamente visada y registrada en el sistema o si se encuentra rechazada. | F35: Requerimiento se basa en las funcionalidades actuales disponibles | G35: Si | H35: No | J35: Inicial | K35: Reuniones - Oferta técnica | L35: Listo | M35: Revisar | N35: SIRH - Piloto
A36: 44 | B36: CONTROL DE ASISTENCIA Y AUSENTISMO | C36: I | D36: APE-04-06 | E36: Firmantes, revisar | F36: Requerimiento se basa en las funcionalidades actuales disponibles | G36: No | H36: No | J36: Inicial | K36: Reuniones - Oferta técnica | L36: Listo | M36: Revisar | N36: SIRH - Piloto
A37: 45 | B37: CONTROL DE ASISTENCIA Y AUSENTISMO | C37: I | D37: APE-04-07 | E37: Mostrar los registros de Licencias médicas con su respectivo detalle. | F37: Requerimiento se basa en las funcionalidades actuales disponibles | G37: Si | H37: No | J37: Inicial | K37: Reuniones - Oferta técnica | L37: Listo | M37: Revisar | N37: SIRH - Piloto
A38: 54 | B38: NOTIFICACIONES E INFORMATIVOS | C38: I | D38: APE-08-01 | E38: Disponibilizar las notificaciones e informativos. | F38: Requerimiento se basa en las funcionalidades actuales disponibles | G38: Si | H38: No | J38: Inicial | K38: Reuniones - Oferta técnica | L38: Listo | M38: Revisar | N38: SIRH - Piloto
A39: 58 | B39: NOTIFICACIONES E INFORMATIVOS | C39: I | D39: APE-08-05 | E39: Notificar aceptación o rechazos de las solicitudes por parte de la jefatura. | F39: Requerimiento se basa en las funcionalidades actuales disponibles | G39: Si | H39: No | J39: Inicial | K39: Reuniones - Oferta técnica | L39: Listo | M39: Revisar | N39: SIRH - Piloto
A40: 59 | B40: NOTIFICACIONES E INFORMATIVOS | C40: I | D40: APE-08-06 | E40: Notificar al personal el comienzo del proceso de acumulación de feriados legales, a su vez, indicar el total de días que pueden y no traspasar. | F40: Corresponde a mensaje llamativo en la vista inicial al usuario (Resumen) desde que se habilita el proceso, además de la notificación. | G40: Si | H40: No | J40: 46157 | K40: Correo | L40: Pendiente | M40: Implementar | N40: Indra | O40: Pendiente carga de FL y horas por vencer
...

Sheet Req. RAD
A1: id | B1: Módulo | C1: Acción | D1: Id Requerimiento | E1: Descripcion segun Doc. B | F1: Perfiles | G1: Origen Doc. A | H1: Estado QA | I1: Acción necesaria | J1: Responsable
A2: 1 | B2: Solicitudes | C2: Programación | D2: RF-001 | E2: Crear solicitud de cupos para uso de campo clínico | F2: CF | G2: 3.4.2 - 2.1.1 | H2: Listo | I2: Validar | J2: Minsal
A3: 2 | B3: Solicitudes | C3: Programación | D3: RF-002 | E3: Guardar solicitud como borrador (sin enviar) | F3: CF | G3: 3.4.2 - 2.1.1 | H3: Listo | I3: Validar | J3: Minsal
A4: 3 | B4: Solicitudes | C4: Programación | D4: RF-003 | E4: Enviar solicitud de cupos a RAD | F4: CF | G4: 3.4.2 - 2.1.1 | H4: Listo | I4: Validar | J4: Minsal
A5: 4 | B5: Solicitudes | C5: Programación | D5: RF-004 | E5: Exportar solicitudes a PDF/Excel | F5: CF | G5: 3.4.2 - 2.1.1 | H5: Pendiente | I5: Construir | J5: Indra
A6: 5 | B6: Solicitudes | C6: Programación | D6: RF-005 | E6: Consultar listado de solicitudes en borrador | F6: CF | G6: 3.4.2 - 2.1.2 | H6: Listo | I6: Validar | J6: Minsal
A7: 6 | B7: Solicitudes | C7: Programación | D7: RF-006 | E7: Editar solicitud en borrador | F7: CF | G7: 3.4.2 - 2.1.2 | H7: Listo | I7: Validar | J7: Minsal
A8: 7 | B8: Solicitudes | C8: Programación | D8: RF-007 | E8: Descartar solicitud en borrador | F8: CF | G8: 3.4.2 - 2.1.2 | H8: Listo | I8: Validar | J8: Minsal
A9: 8 | B9: Solicitudes | C9: Programación | D9: RF-008 | E9: Enviar múltiples solicitudes en bloque | F9: CF | G9: 3.4.2 - 2.1.2 | H9: Listo | I9: Validar | J9: Minsal
A10: 9 | B10: Solicitudes | C10: Programación | D10: RF-009 | E10: Consultar solicitudes enviadas con seguimiento de estados | F10: CF | G10: 3.4.2 - 2.1.3 | H10: Listo | I10: Validar | J10: Minsal
A11: 10 | B11: Solicitudes | C11: Programación | D11: RF-010 | E11: Ver historial de cambios de una solicitud (trazabilidad) | F11: CF | G11: 3.4.2 - 2.1.3 | H11: Listo | I11: Validar | J11: Minsal
A12: 11 | B12: Solicitudes | C12: Programación | D12: RF-011 | E12: Editar y reenviar solicitud rechazada | F12: CF | G12: 3.4.2 - 2.1.3 | H12: Listo | I12: Validar | J12: Minsal
A13: 12 | B13: Solicitudes | C13: Programación | D13: RF-012 | E13: Ratificar o rechazar solicitud aprobada por RAD | F13: CF | G13: 3.4.2 - 2.1.3 | H13: Listo | I13: Validar | J13: Minsal
A14: 13 | B14: Solicitudes | C14: Programación | D14: RF-013 | E14: Notificar cambios de estado de solicitud por correo | F14: CF, RAD | G14: 3.4.2 - 2.1.3 | H14: Listo | I14: Validar | J14: Minsal
